[2023-01-07T21:16:46.523+0000] {taskinstance.py:1165} INFO - Dependencies all met for <TaskInstance: user_processing.create_table scheduled__2023-01-06T00:00:00+00:00 [queued]>
[2023-01-07T21:16:46.541+0000] {taskinstance.py:1165} INFO - Dependencies all met for <TaskInstance: user_processing.create_table scheduled__2023-01-06T00:00:00+00:00 [queued]>
[2023-01-07T21:16:46.541+0000] {taskinstance.py:1362} INFO - 
--------------------------------------------------------------------------------
[2023-01-07T21:16:46.541+0000] {taskinstance.py:1363} INFO - Starting attempt 1 of 1
[2023-01-07T21:16:46.541+0000] {taskinstance.py:1364} INFO - 
--------------------------------------------------------------------------------
[2023-01-07T21:16:46.558+0000] {taskinstance.py:1383} INFO - Executing <Task(PostgresOperator): create_table> on 2023-01-06 00:00:00+00:00
[2023-01-07T21:16:46.567+0000] {standard_task_runner.py:55} INFO - Started process 139 to run task
[2023-01-07T21:16:46.572+0000] {standard_task_runner.py:82} INFO - Running: ['***', 'tasks', 'run', 'user_processing', 'create_table', 'scheduled__2023-01-06T00:00:00+00:00', '--job-id', '9', '--raw', '--subdir', 'DAGS_FOLDER/user_processing.py', '--cfg-path', '/tmp/tmp8t9e_vhh']
[2023-01-07T21:16:46.573+0000] {standard_task_runner.py:83} INFO - Job 9: Subtask create_table
[2023-01-07T21:16:46.639+0000] {task_command.py:376} INFO - Running <TaskInstance: user_processing.create_table scheduled__2023-01-06T00:00:00+00:00 [running]> on host 274e1da73cdf
[2023-01-07T21:16:46.725+0000] {taskinstance.py:1592} INFO - Exporting the following env vars:
AIRFLOW_CTX_DAG_OWNER=***
AIRFLOW_CTX_DAG_ID=user_processing
AIRFLOW_CTX_TASK_ID=create_table
AIRFLOW_CTX_EXECUTION_DATE=2023-01-06T00:00:00+00:00
AIRFLOW_CTX_TRY_NUMBER=1
AIRFLOW_CTX_DAG_RUN_ID=scheduled__2023-01-06T00:00:00+00:00
[2023-01-07T21:16:46.749+0000] {taskinstance.py:1851} ERROR - Task failed with exception
Traceback (most recent call last):
  File "/home/airflow/.local/lib/python3.7/site-packages/airflow/providers/postgres/operators/postgres.py", line 94, in execute
    self.hook.run(self.sql, self.autocommit, parameters=self.parameters)
  File "/home/airflow/.local/lib/python3.7/site-packages/airflow/providers/common/sql/hooks/sql.py", line 288, in run
    with closing(self.get_conn()) as conn:
  File "/home/airflow/.local/lib/python3.7/site-packages/airflow/providers/postgres/hooks/postgres.py", line 88, in get_conn
    conn = deepcopy(self.connection or self.get_connection(conn_id))
  File "/home/airflow/.local/lib/python3.7/site-packages/airflow/hooks/base.py", line 70, in get_connection
    conn = Connection.get_connection_from_secrets(conn_id)
  File "/home/airflow/.local/lib/python3.7/site-packages/airflow/models/connection.py", line 432, in get_connection_from_secrets
    raise AirflowNotFoundException(f"The conn_id `{conn_id}` isn't defined")
airflow.exceptions.AirflowNotFoundException: The conn_id `postgres` isn't defined
[2023-01-07T21:16:46.753+0000] {taskinstance.py:1406} INFO - Marking task as FAILED. dag_id=user_processing, task_id=create_table, execution_date=20230106T000000, start_date=20230107T211646, end_date=20230107T211646
[2023-01-07T21:16:46.771+0000] {standard_task_runner.py:105} ERROR - Failed to execute job 9 for task create_table (The conn_id `postgres` isn't defined; 139)
[2023-01-07T21:16:46.784+0000] {local_task_job.py:164} INFO - Task exited with return code 1
[2023-01-07T21:16:46.800+0000] {local_task_job.py:273} INFO - 0 downstream tasks scheduled from follow-on schedule check
