[2023-01-27T00:30:27.904+0000] {taskinstance.py:1165} INFO - Dependencies all met for <TaskInstance: consumer.read_dataset manual__2023-01-27T00:30:27.500463+00:00 [queued]>
[2023-01-27T00:30:27.918+0000] {taskinstance.py:1165} INFO - Dependencies all met for <TaskInstance: consumer.read_dataset manual__2023-01-27T00:30:27.500463+00:00 [queued]>
[2023-01-27T00:30:27.918+0000] {taskinstance.py:1362} INFO - 
--------------------------------------------------------------------------------
[2023-01-27T00:30:27.919+0000] {taskinstance.py:1363} INFO - Starting attempt 1 of 1
[2023-01-27T00:30:27.919+0000] {taskinstance.py:1364} INFO - 
--------------------------------------------------------------------------------
[2023-01-27T00:30:27.937+0000] {taskinstance.py:1383} INFO - Executing <Task(_PythonDecoratedOperator): read_dataset> on 2023-01-27 00:30:27.500463+00:00
[2023-01-27T00:30:27.944+0000] {standard_task_runner.py:55} INFO - Started process 497 to run task
[2023-01-27T00:30:27.946+0000] {standard_task_runner.py:82} INFO - Running: ['***', 'tasks', 'run', 'consumer', 'read_dataset', 'manual__2023-01-27T00:30:27.500463+00:00', '--job-id', '339', '--raw', '--subdir', 'DAGS_FOLDER/consumer.py', '--cfg-path', '/tmp/tmpzy2tzxvy']
[2023-01-27T00:30:27.947+0000] {standard_task_runner.py:83} INFO - Job 339: Subtask read_dataset
[2023-01-27T00:30:27.989+0000] {task_command.py:376} INFO - Running <TaskInstance: consumer.read_dataset manual__2023-01-27T00:30:27.500463+00:00 [running]> on host bca0acb01f66
[2023-01-27T00:30:28.053+0000] {taskinstance.py:1592} INFO - Exporting the following env vars:
AIRFLOW_CTX_DAG_OWNER=***
AIRFLOW_CTX_DAG_ID=consumer
AIRFLOW_CTX_TASK_ID=read_dataset
AIRFLOW_CTX_EXECUTION_DATE=2023-01-27T00:30:27.500463+00:00
AIRFLOW_CTX_TRY_NUMBER=1
AIRFLOW_CTX_DAG_RUN_ID=manual__2023-01-27T00:30:27.500463+00:00
[2023-01-27T00:30:28.054+0000] {taskinstance.py:1851} ERROR - Task failed with exception
Traceback (most recent call last):
  File "/home/airflow/.local/lib/python3.7/site-packages/airflow/decorators/base.py", line 188, in execute
    return_value = super().execute(context)
  File "/home/airflow/.local/lib/python3.7/site-packages/airflow/operators/python.py", line 175, in execute
    return_value = self.execute_callable()
  File "/home/airflow/.local/lib/python3.7/site-packages/airflow/operators/python.py", line 193, in execute_callable
    return self.python_callable(*self.op_args, **self.op_kwargs)
  File "/opt/airflow/dags/consumer.py", line 18, in read_dataset
    with open(my_file.uri, 'r') as f:
FileNotFoundError: [Errno 2] No such file or directory: '/tmp/my_file.txt'
[2023-01-27T00:30:28.061+0000] {taskinstance.py:1406} INFO - Marking task as FAILED. dag_id=consumer, task_id=read_dataset, execution_date=20230127T003027, start_date=20230127T003027, end_date=20230127T003028
[2023-01-27T00:30:28.071+0000] {standard_task_runner.py:105} ERROR - Failed to execute job 339 for task read_dataset ([Errno 2] No such file or directory: '/tmp/my_file.txt'; 497)
[2023-01-27T00:30:28.117+0000] {local_task_job.py:164} INFO - Task exited with return code 1
[2023-01-27T00:30:28.135+0000] {local_task_job.py:273} INFO - 0 downstream tasks scheduled from follow-on schedule check
