[2023-02-01T00:00:01.546+0000] {taskinstance.py:1165} INFO - Dependencies all met for <TaskInstance: user_processing.create_table scheduled__2023-01-31T12:00:00+00:00 [queued]>
[2023-02-01T00:00:01.553+0000] {taskinstance.py:1165} INFO - Dependencies all met for <TaskInstance: user_processing.create_table scheduled__2023-01-31T12:00:00+00:00 [queued]>
[2023-02-01T00:00:01.553+0000] {taskinstance.py:1362} INFO - 
--------------------------------------------------------------------------------
[2023-02-01T00:00:01.553+0000] {taskinstance.py:1363} INFO - Starting attempt 1 of 1
[2023-02-01T00:00:01.553+0000] {taskinstance.py:1364} INFO - 
--------------------------------------------------------------------------------
[2023-02-01T00:00:01.563+0000] {taskinstance.py:1383} INFO - Executing <Task(PostgresOperator): create_table> on 2023-01-31 12:00:00+00:00
[2023-02-01T00:00:01.566+0000] {standard_task_runner.py:55} INFO - Started process 1191 to run task
[2023-02-01T00:00:01.568+0000] {standard_task_runner.py:82} INFO - Running: ['***', 'tasks', 'run', 'user_processing', 'create_table', 'scheduled__2023-01-31T12:00:00+00:00', '--job-id', '418', '--raw', '--subdir', 'DAGS_FOLDER/user_processing.py', '--cfg-path', '/tmp/tmpcczjq5wr']
[2023-02-01T00:00:01.569+0000] {standard_task_runner.py:83} INFO - Job 418: Subtask create_table
[2023-02-01T00:00:01.610+0000] {task_command.py:376} INFO - Running <TaskInstance: user_processing.create_table scheduled__2023-01-31T12:00:00+00:00 [running]> on host 35d887eb39bb
[2023-02-01T00:00:01.659+0000] {taskinstance.py:1592} INFO - Exporting the following env vars:
AIRFLOW_CTX_DAG_OWNER=***
AIRFLOW_CTX_DAG_ID=user_processing
AIRFLOW_CTX_TASK_ID=create_table
AIRFLOW_CTX_EXECUTION_DATE=2023-01-31T12:00:00+00:00
AIRFLOW_CTX_TRY_NUMBER=1
AIRFLOW_CTX_DAG_RUN_ID=scheduled__2023-01-31T12:00:00+00:00
[2023-02-01T00:00:01.665+0000] {base.py:71} INFO - Using connection ID 'postgres' for task execution.
[2023-02-01T00:00:01.667+0000] {sql.py:315} INFO - Running statement: 
            CREATE TABLE IF NOT EXISTS users (
                firstname TEXT NOT NULL,
                lastname TEXT NOT NULL,
                country TEXT NOT NULL,
                username TEXT NOT NULL,
                password TEXT NOT NULL,
                email TEXT NOT NULL
            )
        , parameters: None
[2023-02-01T00:00:01.668+0000] {postgres.py:96} INFO - NOTICE:  relation "users" already exists, skipping

[2023-02-01T00:00:01.674+0000] {taskinstance.py:1406} INFO - Marking task as SUCCESS. dag_id=user_processing, task_id=create_table, execution_date=20230131T120000, start_date=20230201T000001, end_date=20230201T000001
[2023-02-01T00:00:01.700+0000] {local_task_job.py:164} INFO - Task exited with return code 0
[2023-02-01T00:00:01.729+0000] {local_task_job.py:273} INFO - 1 downstream tasks scheduled from follow-on schedule check
[2023-02-01T01:14:23.012+0000] {taskinstance.py:1165} INFO - Dependencies all met for <TaskInstance: user_processing.create_table scheduled__2023-01-31T12:00:00+00:00 [queued]>
[2023-02-01T01:14:23.019+0000] {taskinstance.py:1165} INFO - Dependencies all met for <TaskInstance: user_processing.create_table scheduled__2023-01-31T12:00:00+00:00 [queued]>
[2023-02-01T01:14:23.019+0000] {taskinstance.py:1362} INFO - 
--------------------------------------------------------------------------------
[2023-02-01T01:14:23.019+0000] {taskinstance.py:1363} INFO - Starting attempt 1 of 1
[2023-02-01T01:14:23.019+0000] {taskinstance.py:1364} INFO - 
--------------------------------------------------------------------------------
[2023-02-01T01:14:23.028+0000] {taskinstance.py:1383} INFO - Executing <Task(PostgresOperator): create_table> on 2023-01-31 12:00:00+00:00
[2023-02-01T01:14:23.032+0000] {standard_task_runner.py:55} INFO - Started process 192 to run task
[2023-02-01T01:14:23.034+0000] {standard_task_runner.py:82} INFO - Running: ['***', 'tasks', 'run', 'user_processing', 'create_table', 'scheduled__2023-01-31T12:00:00+00:00', '--job-id', '32', '--raw', '--subdir', 'DAGS_FOLDER/user_processing.py', '--cfg-path', '/tmp/tmpo7i0ns_x']
[2023-02-01T01:14:23.035+0000] {standard_task_runner.py:83} INFO - Job 32: Subtask create_table
[2023-02-01T01:14:23.074+0000] {task_command.py:376} INFO - Running <TaskInstance: user_processing.create_table scheduled__2023-01-31T12:00:00+00:00 [running]> on host 1315be86012b
[2023-02-01T01:14:23.117+0000] {taskinstance.py:1592} INFO - Exporting the following env vars:
AIRFLOW_CTX_DAG_OWNER=***
AIRFLOW_CTX_DAG_ID=user_processing
AIRFLOW_CTX_TASK_ID=create_table
AIRFLOW_CTX_EXECUTION_DATE=2023-01-31T12:00:00+00:00
AIRFLOW_CTX_TRY_NUMBER=1
AIRFLOW_CTX_DAG_RUN_ID=scheduled__2023-01-31T12:00:00+00:00
[2023-02-01T01:14:23.128+0000] {taskinstance.py:1851} ERROR - Task failed with exception
Traceback (most recent call last):
  File "/home/airflow/.local/lib/python3.7/site-packages/airflow/providers/postgres/operators/postgres.py", line 94, in execute
    self.hook.run(self.sql, self.autocommit, parameters=self.parameters)
  File "/home/airflow/.local/lib/python3.7/site-packages/airflow/providers/common/sql/hooks/sql.py", line 288, in run
    with closing(self.get_conn()) as conn:
  File "/home/airflow/.local/lib/python3.7/site-packages/airflow/providers/postgres/hooks/postgres.py", line 88, in get_conn
    conn = deepcopy(self.connection or self.get_connection(conn_id))
  File "/home/airflow/.local/lib/python3.7/site-packages/airflow/hooks/base.py", line 70, in get_connection
    conn = Connection.get_connection_from_secrets(conn_id)
  File "/home/airflow/.local/lib/python3.7/site-packages/airflow/models/connection.py", line 432, in get_connection_from_secrets
    raise AirflowNotFoundException(f"The conn_id `{conn_id}` isn't defined")
airflow.exceptions.AirflowNotFoundException: The conn_id `postgres` isn't defined
[2023-02-01T01:14:23.131+0000] {taskinstance.py:1406} INFO - Marking task as FAILED. dag_id=user_processing, task_id=create_table, execution_date=20230131T120000, start_date=20230201T011423, end_date=20230201T011423
[2023-02-01T01:14:23.138+0000] {standard_task_runner.py:105} ERROR - Failed to execute job 32 for task create_table (The conn_id `postgres` isn't defined; 192)
[2023-02-01T01:14:23.165+0000] {local_task_job.py:164} INFO - Task exited with return code 1
[2023-02-01T01:14:23.193+0000] {local_task_job.py:273} INFO - 0 downstream tasks scheduled from follow-on schedule check
