[2023-01-07T21:25:26.891+0000] {taskinstance.py:1165} INFO - Dependencies all met for <TaskInstance: user_processing.process_user manual__2023-01-07T21:25:25.448316+00:00 [queued]>
[2023-01-07T21:25:26.899+0000] {taskinstance.py:1165} INFO - Dependencies all met for <TaskInstance: user_processing.process_user manual__2023-01-07T21:25:25.448316+00:00 [queued]>
[2023-01-07T21:25:26.899+0000] {taskinstance.py:1362} INFO - 
--------------------------------------------------------------------------------
[2023-01-07T21:25:26.900+0000] {taskinstance.py:1363} INFO - Starting attempt 1 of 1
[2023-01-07T21:25:26.900+0000] {taskinstance.py:1364} INFO - 
--------------------------------------------------------------------------------
[2023-01-07T21:25:26.912+0000] {taskinstance.py:1383} INFO - Executing <Task(PythonOperator): process_user> on 2023-01-07 21:25:25.448316+00:00
[2023-01-07T21:25:26.916+0000] {standard_task_runner.py:55} INFO - Started process 598 to run task
[2023-01-07T21:25:26.919+0000] {standard_task_runner.py:82} INFO - Running: ['***', 'tasks', 'run', 'user_processing', 'process_user', 'manual__2023-01-07T21:25:25.448316+00:00', '--job-id', '20', '--raw', '--subdir', 'DAGS_FOLDER/user_processing.py', '--cfg-path', '/tmp/tmpcotvrhse']
[2023-01-07T21:25:26.920+0000] {standard_task_runner.py:83} INFO - Job 20: Subtask process_user
[2023-01-07T21:25:26.962+0000] {task_command.py:376} INFO - Running <TaskInstance: user_processing.process_user manual__2023-01-07T21:25:25.448316+00:00 [running]> on host 274e1da73cdf
[2023-01-07T21:25:27.012+0000] {taskinstance.py:1592} INFO - Exporting the following env vars:
AIRFLOW_CTX_DAG_OWNER=***
AIRFLOW_CTX_DAG_ID=user_processing
AIRFLOW_CTX_TASK_ID=process_user
AIRFLOW_CTX_EXECUTION_DATE=2023-01-07T21:25:25.448316+00:00
AIRFLOW_CTX_TRY_NUMBER=1
AIRFLOW_CTX_DAG_RUN_ID=manual__2023-01-07T21:25:25.448316+00:00
[2023-01-07T21:25:27.013+0000] {taskinstance.py:1851} ERROR - Task failed with exception
Traceback (most recent call last):
  File "/home/airflow/.local/lib/python3.7/site-packages/airflow/operators/python.py", line 175, in execute
    return_value = self.execute_callable()
  File "/home/airflow/.local/lib/python3.7/site-packages/airflow/operators/python.py", line 193, in execute_callable
    return self.python_callable(*self.op_args, **self.op_kwargs)
  File "/opt/airflow/dags/user_processing.py", line 12, in _process_user_
    user = ti.xcom_pull(task_id = 'extract_user')
  File "/home/airflow/.local/lib/python3.7/site-packages/airflow/utils/session.py", line 75, in wrapper
    return func(*args, session=session, **kwargs)
TypeError: xcom_pull() got an unexpected keyword argument 'task_id'
[2023-01-07T21:25:27.019+0000] {taskinstance.py:1406} INFO - Marking task as FAILED. dag_id=user_processing, task_id=process_user, execution_date=20230107T212525, start_date=20230107T212526, end_date=20230107T212527
[2023-01-07T21:25:27.027+0000] {standard_task_runner.py:105} ERROR - Failed to execute job 20 for task process_user (xcom_pull() got an unexpected keyword argument 'task_id'; 598)
[2023-01-07T21:25:27.050+0000] {local_task_job.py:164} INFO - Task exited with return code 1
[2023-01-07T21:25:27.062+0000] {local_task_job.py:273} INFO - 0 downstream tasks scheduled from follow-on schedule check
